Workbook

Sheet Round 1
B1: Position | C1: Player | D1: Team | E1: Points | H1: Notes
A2: Ben | B2: Forward 1 | C2: Nathan MacKinnon | D2: Avalanche | E2: 9 | H2: Goalie points - 2 ponts per win + 2 for shutout
B3: Forward 2 | C3: Brad Marchand | D3: Bruins | E3: 8
B4: Forward 3 | C4: Alex Ovechkin | D4: Capitals | E4: 0
B5: Forward 4 | C5: Elias Petterson | D5: Canucks | E5: 3
B6: Forward 5 | C6: Ross Colton | D6: Avalanche | E6: 3
B7: Defense 1 | C7: Noah Dobson | D7: Islanders | E7: 1
B8: Defense 2 | C8: Shea Theodore | D8: Knights | E8: 0
B9: Defense 3 | C9: Charlie McAvoy | D9: Bruins | E9: 4 | G9: Order
B10: Goalie 1 | C10: Panthers Goalie (Sergei Bobrovsky) | D10: Panthers | E10: 8 | G10: Levi
B11: Total | E11: =sum(E2:E10) -> 36 | G11: Ben
A12: Judah | B12: Forward 1 | C12: Leon Draisaitl | D12: Oilers | E12: 10 | G12: Kyle
B13: Forward 2 | C13: JT Miller | D13: Canucks | E13: 6 | G13: Judah
B14: Forward 3 | C14: Matthew Tkachuk | D14: Panthers | E14: 9
B15: Forward 4 | C15: Jonathan Marchessault | D15: Knights | E15: 4 | G15: Last Updated
B16: Forward 5 | C16: Corey Perry | D16: Oilers | E16: 0 | G16: 45417
B17: Defense 1 | C17: Quinn Hughes | D17: Canucks | E17: 5
B18: Defense 2 | C18: Victor Hedman | D18: Lightning | E18: 7 | G18: Current Max
B19: Defense 3 | C19: Drew Doughty | D19: Kings | E19: 3 | G19: =MAX(E11, E21, E31, E41) -> 53
B20: Goalie 1 | C20: Rangers (Igor Shesterkin) | D20: Rangers | E20: 8
B21: Total | E21: =sum(E12:E20) -> 52 | G21: Current Winner
A22: Kyle | B22: Forward 1 | C22: Nikita Kucherov | D22: Lightning | E22: 7 | G22: {=INDIRECT(ADDRESS(1+MATCH(G19, E11:E41, 0), 1))} -> Kyle
B23: Forward 2 | C23: David Pastrnak | D23: Bruins | E23: 5
B24: Forward 3 | C24: Mikko Rantanen | D24: Avalanche | E24: 9 | F24: Points when drafted | G24: Current Points
B25: Forward 4 | C25: Zach Hyman | D25: Oilers | E25: =G25-F25 -> 3 | F25: 5 | G25: 8
B26: Forward 5 | C26: Jake DeBrusk | D26: Bruins | E26: 5
B27: Defense 1 | C27: Evan Bouchard | D27: Oilers | E27: 9 | H27: Statistics
B28: Defense 2 | C28: Adam Fox | D28: Rangers | E28: 2
B29: Defense 3 | C29: Morgan Rielly | D29: Leafs | E29: 3
B30: Goalie 1 | C30: Canucks Goalie (Thatcher Demko) | D30: Canucks | E30: 10
B31: Total | E31: =sum(E22:E30) -> 53 | H31: Scoring
A32: Levi | B32: Forward 1 | C32: Connor McDavid | D32: Oilers | E32: 12 | H32: Points = goals + assists.
B33: Forward 2 | C33: Auston Matthews | D33: Leafs | E33: 4 | H33: goalie is 2 points/win + 2 for shutouts
B34: Forward 3 | C34: Artemi Panarin | D34: Rangers | E34: 3
B35: Forward 4 | C35: Mitch Marner | D35: Leafs | E35: 3
B36: Forward 5 | C36: Pierre-Luc Dubois | D36: Kings | E36: 1 | H36: Teams Scored
B37: Defense 1 | C37: Cale Makar | D37: Avalanche | E37: 9
B38: Defense 2 | C38: Roman Josi | D38: Predators | E38: 3
B39: Defense 3 | C39: Josh Morrissey | D39: Jets | E39: 4 | H39: Round 1 Point Potential per Series
B40: Goalie 1 | C40: Hurricanes Goalie (Pyotr Kochetkov) | D40: Hurricanes | E40: 8 | H40: =(SUM(E2:E10) + SUM(E12:E20) + SUM(E22:E30) + SUM(E32:E40)) / 8 -> 23.5
...

Sheet Round 2
B1: Position | C1: Player | D1: Team | E1: Points for Round | F1: Points when drafted | G1: Current Total Points | J1: Notes
A2: Ben | B2: Forward 1 | C2: Nathan MacKinnon | D2: Avalanche | E2: =G2 - F2 -> 5 | F2: 9 | G2: 14 | J2: Goalie points - 2 ponts per win + 2 for shutout
B3: Forward 2 | C3: Brad Marchand | D3: Bruins | E3: =G3 - F3 -> 2 | F3: 8 | G3: 10
B4: Forward 3 | C4: Carter Verhaeghe | D4: Panthers | E4: =G4 - F4 -> 2 | F4: 9 | G4: 11
B5: Forward 4 | C5: Elias Petterson | D5: Canucks | E5: =G5 - F5 -> 3 | F5: 3 | G5: 6
B6: Forward 5 | C6: Seth Jarvis | D6: Hurricanes | E6: =G6 - F6 -> 2 | F6: 7 | G6: 9
B7: Defense 1 | C7: Brady Skijei | D7: Hurricanes | E7: =G7 - F7 -> 4 | F7: 5 | G7: 9
B8: Defense 2 | C8: Josh Manson | D8: Avalanche | E8: =G8 - F8 -> 2 | F8: 5 | G8: 7
B9: Defense 3 | C9: Charlie McAvoy | D9: Bruins | E9: =G9 - F9 -> 2 | F9: 4 | G9: 6 | I9: Order
B10: Goalie 1 | C10: Panthers Goalie (Sergei Bobrovsky) | D10: Panthers | E10: =G10 - F10 -> 8 | F10: 0 | G10: 8 | I10: Ben
B11: Total across Rounds | E11: =sum(E2:E10) + 'Round 1'!E11 -> 66 | I11: Levi
A12: Judah | B12: Forward 1 | C12: Leon Draisaitl | D12: Oilers | E12: =G12 - F12 -> 14 | F12: 10 | G12: 24 | I12: Judah
B13: Forward 2 | C13: JT Miller | D13: Canucks | E13: =G13 - F13 -> 6 | F13: 6 | G13: 12 | I13: Kyle
B14: Forward 3 | C14: Matthew Tkachuk | D14: Panthers | E14: =G14 - F14 -> 5 | F14: 9 | G14: 14
B15: Forward 4 | C15: Chris Kreider | D15: Rangers | E15: =G15 - F15 -> 5 | F15: 5 | G15: 10 | I15: Last Updated
B16: Forward 5 | C16: David Pastrank | D16: Bruins | E16: =G16 - F16 -> 3 | F16: 5 | G16: 8 | I16: 45433
B17: Defense 1 | C17: Quinn Hughes | D17: Canucks | E17: =G17 - F17 -> 5 | F17: 5 | G17: 10
B18: Defense 2 | C18: Nikita Zadorov | D18: Canucks | E18: =G18 - F18 -> 5 | F18: 3 | G18: 8 | I18: Current Max
B19: Defense 3 | C19: Devon Toews | D19: Avalanche | E19: =G19 - F19 -> 1 | F19: 5 | G19: 6 | I19: =MAX(E11, E21, E31, E41) -> 108
B20: Goalie 1 | C20: Rangers (Igor Shesterkin) | D20: Rangers | E20: =G20 - F20 -> 8 | F20: 0 | G20: 8
B21: Total across Rounds | E21: =sum(E12:E20) + 'Round 1'!E21 -> 104 | I21: Current Winner
A22: Kyle | B22: Forward 1 | C22: Artturi Lehkonen | D22: Avalanche | E22: =G22 - F22 -> 3 | F22: 8 | G22: 11 | I22: {=INDIRECT(ADDRESS(1+MATCH(I19, E11:E41, 0), 1))} -> Levi
B23: Forward 2 | C23: Mika Zibanejad | D23: Rangers | E23: =G23 - F23 -> 5 | F23: 9 | G23: 14
B24: Forward 3 | C24: Mikko Rantanen | D24: Avalanche | E24: =G24 - F24 -> 5 | F24: 9 | G24: 14
B25: Forward 4 | C25: Zach Hyman | D25: Oilers | E25: =G25 - F25 -> 5 | F25: 8 | G25: 13
B26: Forward 5 | C26: Vincent Trocheck | D26: Rangers | E26: =G26 - F26 -> 7 | F26: 7 | G26: 14
B27: Defense 1 | C27: Evan Bouchard | D27: Oilers | E27: =G27 - F27 -> 11 | F27: 9 | G27: 20 | J27: Statistics
B28: Defense 2 | C28: Hampus Lindholm | D28: Bruins | E28: =G28 - F28 -> 0 | F28: 4 | G28: 4
B29: Defense 3 | C29: Gustav Forsling | D29: Panthers | E29: =G29 - F29 -> 4 | F29: 3 | G29: 7
B30: Goalie 1 | C30: Oilers Goalie | D30: Oilers | E30: =G30 - F30 -> 8 | F30: 0 | G30: 8
B31: Total across Rounds | E31: =sum(E22:E30) + 'Round 1'!E31 -> 101 | J31: Scoring
A32: Levi | B32: Forward 1 | C32: Connor McDavid | D32: Oilers | E32: =G32 - F32 -> 9 | F32: 12 | G32: 21 | J32: Points = goals + assists.
B33: Forward 2 | C33: Ryan Nugent-Hopkins | D33: Oilers | E33: =G33 - F33 -> 10 | F33: 6 | G33: 16 | J33: goalie is 2 points/win + 2 for shutouts
B34: Forward 3 | C34: Artemi Panarin | D34: Rangers | E34: =G34 - F34 -> 8 | F34: 3 | G34: 11
B35: Forward 4 | C35: Aleksander Barkov | D35: Panthers | E35: =G35 - F35 -> 8 | F35: 5 | G35: 13
B36: Forward 5 | C36: Brock Boeser | D36: Canucks | E36: =G36 - F36 -> 6 | F36: 6 | G36: 12 | J36: Teams Scored
B37: Defense 1 | C37: Cale Makar | D37: Avalanche | E37: =G37 - F37 -> 6 | F37: 9 | G37: 15
B38: Defense 2 | C38: Adam Fox | D38: Rangers | E38: =G38 - F38 -> 2 | F38: 2 | G38: 4
B39: Defense 3 | C39: Miro Heiskanen | D39: Stars | E39: =G39 - F39 -> 8 | F39: 5 | G39: 13 | J39: Round 2 Point Potential per Series
B40: Goalie 1 | C40: Avalanche Goalie | D40: Avalanche | E40: =G40 - F40 -> 4 | F40: 0 | G40: 4 | J40: =(SUM(E2:E10) + SUM(E12:E20) + SUM(E22:E30) + SUM(E32:E40)) / 4 -> 47.75
...

Sheet Round 3 + Round 4
B1: Position | C1: Player | D1: Team | E1: Points for Round | F1: Points when drafted | G1: Current Total Points | J1: Notes
A2: Ben | B2: Forward 1 | C2: Sam Reinhart | D2: Panthers | E2: =G2 - F2 -> 7 | F2: 9 | G2: 16 | J2: Goalie points - 2 ponts per win + 2 for shutout
B3: Forward 2 | C3: Anton Lundell | D3: Panthers | E3: =G3 - F3 -> 8 | F3: 9 | G3: 17
B4: Forward 3 | C4: Carter Verhaeghe | D4: Panthers | E4: =G4 - F4 -> 10 | F4: 11 | G4: 21
B5: Forward 4 | C5: Vladimir Tarasenko | D5: Panthers | E5: =G5 - F5 -> 4 | F5: 5 | G5: 9
B6: Forward 5 | C6: Sam Bennett | D6: Panthers | E6: =G6 - F6 -> 12 | F6: 4 | G6: 16
B7: Defense 1 | C7: Dmitry Kulikov | D7: Panthers | E7: =3 + (G7 - F7) -> 5 | F7: 0 | G7: 2 | H7: (+3 because of Jacob Trouba for Round 3)
B8: Defense 2 | C8: Aaraon Ekblad | D8: Panthers | E8: =G8 - F8 -> 2 | F8: 4 | G8: 6
B9: Defense 3 | C9: Niko Mikkola | D9: Panthers | E9: =G9 - F9 -> 2 | F9: 2 | G9: 4 | I9: Order
B10: Goalie 1 | C10: Panthers Goalie (Sergei Bobrovsky) | D10: Panthers | E10: =G10 - F10 -> 20 | F10: 0 | G10: 20 | I10: Ben
B11: Total across Rounds | E11: =sum(E2:E10) + 'Round 2'!E11 -> 136 | I11: Kyle
A12: Judah | B12: Forward 1 | C12: Connor McDavid | D12: Oilers | E12: =G12-F12 -> 21 | F12: 21 | G12: 42 | I12: Judah
B13: Forward 2 | C13: Wyatt Johnston | D13: Stars | E13: =G13-F13 -> 5 | F13: 11 | G13: 16 | I13: Levi
B14: Forward 3 | C14: Matthew Tkachuk | D14: Panthers | E14: =G14-F14 -> 8 | F14: 14 | G14: 22
B15: Forward 4 | C15: Chris Kreider | D15: Rangers | E15: =G15-F15 -> 2 | F15: 10 | G15: 12 | I15: Last Updated
B16: Forward 5 | C16: Jamie Benn | D16: Stars | E16: =G16-F16 -> 7 | F16: 8 | G16: 15 | I16: 45443
B17: Defense 1 | C17: Oliver Ekman-Larsson | D17: Panthers | E17: =G17-F17 -> 2 | F17: 4 | G17: 6
B18: Defense 2 | C18: K'Andre Miller | D18: Rangers | E18: =G18-F18 -> 1 | F18: 3 | G18: 4 | I18: Current Max
B19: Defense 3 | C19: Cody Ceci | D19: Oilers | E19: =G19-F19 -> 2 | F19: 3 | G19: 5 | I19: =MAX(E11, E21, E31, E41) -> 172
B20: Goalie 1 | C20: Rangers Goalie (Igor Shesterkin) | D20: Rangers | E20: =G20-F20 -> 4 | F20: 0 | G20: 4
B21: Total across Rounds | E21: =sum(E12:E20) + 'Round 2'!E21 -> 156 | I21: Current Winner
A22: Kyle | B22: Forward 1 | C22: Jason Robertson | D22: Stars | E22: =G22-F22 -> 4 | F22: 12 | G22: 16 | I22: {=INDIRECT(ADDRESS(1+MATCH(I19, E11:E41, 0), 1))} -> Levi
B23: Forward 2 | C23: Tyler Seguin | D23: Stars | E23: =G23-F23 -> 5 | F23: 8 | G23: 13
B24: Forward 3 | C24: Roope Hintz | D24: Stars | E24: =G24-F24 -> 2 | F24: 6 | G24: 8
B25: Forward 4 | C25: Ryan Nugent-Hopkins | D25: Oilers | E25: =G25-F25 -> 6 | F25: 16 | G25: 22
B26: Forward 5 | C26: Evan Rodrigues | D26: Panthers | E26: =G26-F26 -> 9 | F26: 6 | G26: 15
B27: Defense 1 | C27: Ryan Suter | D27: Stars | E27: =G27-F27 -> 1 | F27: 3 | G27: 4 | J27: Statistics
B28: Defense 2 | C28: Brandon Mountour | D28: Panthers | E28: =G28-F28 -> 3 | F28: 8 | G28: 11
B29: Defense 3 | C29: Gustav Forsling | D29: Panthers | E29: =G29-F29 -> 6 | F29: 7 | G29: 13
B30: Goalie 1 | C30: Stars Goalie (Jake Oettinger) | D30: Stars | E30: =G30-F30 -> 4 | F30: 0 | G30: 4
B31: Total across Rounds | E31: =sum(E22:E30) + 'Round 2'!E31 -> 141 | J31: Scoring
A32: Levi | B32: Forward 1 | C32: McDavid | D32: Oilers | E32: =G32-F32 -> 7 | F32: 24 | G32: 31 | J32: Points = goals + assists.
B33: Forward 2 | C33: Zach Hyman | D33: Oilers | E33: =G33-F33 -> 9 | F33: 13 | G33: 22 | J33: goalie is 2 points/win + 2 for shutouts
B34: Forward 3 | C34: Artemi Panarin | D34: Rangers | E34: =G34-F34 -> 4 | F34: 11 | G34: 15
B35: Forward 4 | C35: Aleksander Barkov | D35: Panthers | E35: =G35-F35 -> 9 | F35: 13 | G35: 22
B36: Forward 5 | C36: Mika Zibanejad | D36: Rangers | E36: =G36-F36 -> 2 | F36: 14 | G36: 16 | J36: Teams Scored
B37: Defense 1 | C37: Makar | D37: Oilers | E37: =G37-F37 -> 12 | F37: 20 | G37: 32
B38: Defense 2 | C38: Adam Fox | D38: Rangers | E38: =G38-F38 -> 4 | F38: 4 | G38: 8
B39: Defense 3 | C39: Miro Heiskanen | D39: Stars | E39: =G39-F39 -> 3 | F39: 13 | G39: 16 | J39: Round 3 Point Potential per Series
B40: Goalie 1 | C40: Oilers Goalie (Stuart Skinner) | D40: Oilers | E40: =G40-F40 -> 14 | F40: 0 | G40: 14 | J40: =(SUM(E2:E10) + SUM(E12:E20) + SUM(E22:E30) + SUM(E32:E40)) / 2 -> 113
...

Sheet Wins
A10: 2014 | C10: Kings
A11: 2015 | C11: Blackhawks
A12: 2016 | C12: Penguins
A13: 2017 | C13: Penguins
A14: 2018 | B14: Ben | C14: Capitals
A15: 2019 | B15: Levi | C15: St. Louis Blues
A16: 2020 | B16: Levi | C16: Lighting
A17: 2021 | B17: Levi | C17: Lighting
A18: 2022 | B18: Levi | C18: Avalanche
A19: 2023 | B19: Kyle | C19: Knights
A20: 2024 | B20: Levi | C20: Panthers
A21: 2025
